Workbook

Sheet Menu
A1: Tier | B1: Repo | C1: Stars | D1: Category | E1: Lang | F1: What it is | G1: Why it's for you | H1: Tags
A2: Structure & Code Viz
A3: GEM | B3: safishamsi/graphify | C3: 54738 | D3: Structure & Code Viz | E3: Python | F3: Code, SQL schemas, docs, images & video → one queryable knowledge graph | G3: Hold your whole multi-stack system (Wix+React+Supabase+NAS) in your head by looking at it | H3: structure, apparatus
A4: GEM | B4: Lum1104/Understand-Anything | C4: 38543 | D4: Structure & Code Viz | E4: TypeScript | F4: Any codebase/docs → interactive knowledge graph you explore & ask questions | G4: Understand what Claude shipped you without reading source | H4: structure
A5: GEM | B5: oh-my-mermaid/oh-my-mermaid | C5: 1254 | D5: Structure & Code Viz | E5: TypeScript | F5: Codebase → navigable Mermaid architecture diagrams | G5: Auto architecture maps — 'AI writes in seconds, humans understand in hours' | H5: structure
A6: GEM | B6: nanoapi-io/napi | C6: 320 | D6: Structure & Code Viz | E6: TypeScript | F6: Offline CLI: analyze architecture (deps/complexity/structure), visualize & refactor | G6: Architecture x-ray, runs offline so client code stays local | H6: structure
A7: GEM | B7: QuinnAho/claudemap | C7: 236 | D7: Structure & Code Viz | E7: JavaScript | F7: 'Google Maps for vibecoders' — map of what you built | G7: Built for the exact can't-read-your-own-code gap | H7: structure
A8: NOTABLE | B8: chunkhound/chunkhound | C8: 1277 | D8: Structure & Code Viz | E8: Python | F8: Local-first codebase intelligence; extracts architecture & patterns | H8: structure
A9: NOTABLE | B9: Jakedismo/codegraph-rust | C9: 773 | D9: Structure & Code Viz | E9: Rust | F9: Codebase → semantic knowledge graph (AST+ML, SurrealDB, MCP) | H9: structure
A10: NOTABLE | B10: proxysoul/soulforge | C10: 714 | D10: Structure & Code Viz | E10: TypeScript | F10: Edits symbols not strings; AST surgery + live code graph wired to memory | H10: structure
A11: NOTABLE | B11: harshkedia177/axon | C11: 706 | D11: Structure & Code Viz | E11: Python | F11: Graph-powered code intelligence, KG via MCP+CLI | H11: structure
A12: NOTABLE | B12: 8b-is/smart-tree | C12: 249 | D12: Structure & Code Viz | E12: Rust | F12: AI-aware `tree` replacement + visual dashboard, semantic search | G12: Visual file tree (ignore the 'quantum' marketing) | H12: structure
A13: NOTABLE | B13: Corbell-AI/Corbell | C13: 212 | D13: Structure & Code Viz | E13: Python | F13: Multi-repo architecture graph + AI spec gen & review | G13: If Pyris/CCF code spans repos | H13: structure
A14: NOTABLE | B14: ozgurcd/gograph | C14: 146 | D14: Structure & Code Viz | E14: Go | F14: Local repo-structure viz (Go-only) | H14: structure
A15: NOTABLE | B15: helixml/kodit | C15: 119 | D15: Structure & Code Viz | E15: Go | F15: Index git repos, search via MCP + REST | H15: structure
A16: NOTABLE | B16: st3v3nmw/sourcerer-mcp | C16: 114 | D16: Structure & Code Viz | E16: Go | F16: Semantic code search & navigation, token reduction | H16: structure
A17: NOTABLE | B17: Lekssays/codebadger | C17: 108 | D17: Structure & Code Viz | E17: Python | F17: Static code analysis via Joern Code Property Graph, 12 languages | H17: structure
A18: Orchestration & Multi-Agent
A19: GEM | B19: nyldn/claude-octopus | C19: 3423 | D19: Orchestration & Multi-Agent | E19: Shell | F19: Run up to 8 models on every task to surface blindspots | G19: Cross-model safety net for a non-coder (you loved this) | H19: orchestration
A20: GEM | B20: asheshgoplani/agent-deck | C20: 2540 | D20: Orchestration & Multi-Agent | E20: Go | F20: TUI session manager for running multiple coding agents | G20: Cockpit for your parallel OC/CC windows | H20: orchestration, adhd
A21: GEM | B21: collaborator-ai/collab-public | C21: 2510 | D21: Orchestration & Multi-Agent | E21: TypeScript | F21: Infinite canvas — terminals, context & code spatially arranged | G21: Spatial workspace for the parallel brain (you loved this) | H21: orchestration, adhd
A22: GEM | B22: patoles/agent-flow | C22: 940 | D22: Orchestration & Multi-Agent | E22: TypeScript | F22: Real-time visualization of agent orchestration — watch them think/branch/coordinate | G22: See your OC/CC coordination live | H22: orchestration
A23: GEM | B23: voicetreelab/voicetree | C23: 853 | D23: Orchestration & Multi-Agent | E23: TypeScript | F23: Spatial IDE — an Obsidian graph-view you work *inside*, recursive multi-agent | G23: collab-public's cousin; nodes are files OR running agents | H23: orchestration, adhd
A24: GEM | B24: kdlbs/kandev | C24: 287 | D24: Orchestration & Multi-Agent | E24: Go | F24: AI Kanban + dev env: orchestrate agents, review changes, open PRs; self-host | G24: Kanban cockpit — your PM brain + parallel agents | H24: orchestration, adhd
A25: GEM | B25: DatafyingTech/Claude-Agent-Team-Manager | C25: 128 | D25: Orchestration & Multi-Agent | E25: TypeScript | F25: Visual org-chart desktop app for managing CC agent teams/skills/configs | G25: Your COO org-chart brain made literal | H25: orchestration
A26: NOTABLE | B26: superset-sh/superset | C26: 11347 | D26: Orchestration & Multi-Agent | E26: TypeScript | F26: Code editor for the agent era; run swarms of agents | H26: orchestration
A27: NOTABLE | B27: ogulcancelik/herdr | C27: 2594 | D27: Orchestration & Multi-Agent | E27: Rust | F27: Agent multiplexer in your terminal | H27: orchestration
A28: NOTABLE | B28: agent-of-empires/agent-of-empires | C28: 2429 | D28: Orchestration & Multi-Agent | E28: Rust | F28: Run multiple agents in parallel, TUI or web/mobile | G28: Mobile access to parallel agents | H28: orchestration
A29: NOTABLE | B29: DeepMyst/Mysti | C29: 1057 | D29: Orchestration & Multi-Agent | E29: TypeScript | F29: VS Code AI dream team — brainstorm, debate, synthesize | H29: orchestration
A30: NOTABLE | B30: marcus/sidecar | C30: 1018 | D30: Orchestration & Multi-Agent | E30: Go | F30: Diffs, file trees, conversation history, task mgmt beside CLI agents | G30: File trees + history in one shell | H30: orchestration
A31: NOTABLE | B31: milisp/codexia | C31: 694 | D31: Orchestration & Multi-Agent | E31: TypeScript | F31: Agent workstation: task scheduler, git worktree, remote control | H31: orchestration
A32: NOTABLE | B32: loocor/codmate | C32: 669 | D32: Orchestration & Multi-Agent | E32: Swift | F32: macOS app to browse/search/resume/review CLI AI sessions | H32: orchestration
A33: NOTABLE | B33: MiniCodeMonkey/chief | C33: 462 | D33: Orchestration & Multi-Agent | E33: Go | F33: Breaks big projects into tasks, runs CC in a loop until done | H33: orchestration
A34: NOTABLE | B34: Ark0N/Codeman | C34: 410 | D34: Orchestration & Multi-Agent | E34: TypeScript | F34: Manage CC/Opencode in tmux via mobile-first WebUI | H34: orchestration
A35: NOTABLE | B35: timwuhaotian/the-pair | C35: 336 | D35: Orchestration & Multi-Agent | E35: TypeScript | F35: Two agents cross-check each other's work | H35: orchestration
A36: NOTABLE | B36: zippoxer/subtask | C36: 331 | D36: Orchestration & Multi-Agent | E36: Go | F36: Subagents in git worktrees, run in parallel | H36: orchestration
A37: NOTABLE | B37: aannoo/hcom | C37: 301 | D37: Orchestration & Multi-Agent | E37: Rust | F37: Agents message/watch/spawn each other across terminals | H37: orchestration
A38: NOTABLE | B38: sudocode-ai/sudocode | C38: 277 | D38: Orchestration & Multi-Agent | E38: TypeScript | F38: Lightweight agent orchestration that lives in your repo | H38: orchestration
A39: NOTABLE | B39: OpenSource03/harnss | C39: 270 | D39: Orchestration & Multi-Agent | E39: TypeScript | F39: Run multiple agents side by side, rich tool visualization | H39: orchestration
A40: NOTABLE | B40: onikan27/claude-code-monitor | C40: 235 | D40: Orchestration & Multi-Agent | E40: TypeScript | F40: Real-time multi-session dashboard, mobile/QR access | H40: orchestration
...

Sheet By Category
A1: Category | B1: GEMs | C1: Notables | D1: Total
A2: Structure & Code Viz | B2: =COUNTIFS(Menu!D:D,A2,Menu!A:A,"GEM") -> 5 | C2: =COUNTIFS(Menu!D:D,A2,Menu!A:A,"NOTABLE") -> 10 | D2: =B2+C2 -> 15
A3: Orchestration & Multi-Agent | B3: =COUNTIFS(Menu!D:D,A3,Menu!A:A,"GEM") -> 7 | C3: =COUNTIFS(Menu!D:D,A3,Menu!A:A,"NOTABLE") -> 17 | D3: =B3+C3 -> 24
A4: Maker & Hardware | B4: =COUNTIFS(Menu!D:D,A4,Menu!A:A,"GEM") -> 4 | C4: =COUNTIFS(Menu!D:D,A4,Menu!A:A,"NOTABLE") -> 4 | D4: =B4+C4 -> 8
A5: Visuals & Deliverables | B5: =COUNTIFS(Menu!D:D,A5,Menu!A:A,"GEM") -> 5 | C5: =COUNTIFS(Menu!D:D,A5,Menu!A:A,"NOTABLE") -> 3 | D5: =B5+C5 -> 8
A6: Design & Brand | B6: =COUNTIFS(Menu!D:D,A6,Menu!A:A,"GEM") -> 2 | C6: =COUNTIFS(Menu!D:D,A6,Menu!A:A,"NOTABLE") -> 7 | D6: =B6+C6 -> 9
A7: Knowledge & Context (PKM) | B7: =COUNTIFS(Menu!D:D,A7,Menu!A:A,"GEM") -> 3 | C7: =COUNTIFS(Menu!D:D,A7,Menu!A:A,"NOTABLE") -> 12 | D7: =B7+C7 -> 15
A8: Templating & Scaffolding | B8: =COUNTIFS(Menu!D:D,A8,Menu!A:A,"GEM") -> 2 | C8: =COUNTIFS(Menu!D:D,A8,Menu!A:A,"NOTABLE") -> 4 | D8: =B8+C8 -> 6
A9: Project & Task | B9: =COUNTIFS(Menu!D:D,A9,Menu!A:A,"GEM") -> 1 | C9: =COUNTIFS(Menu!D:D,A9,Menu!A:A,"NOTABLE") -> 3 | D9: =B9+C9 -> 4
A10: Ops & Automation | B10: =COUNTIFS(Menu!D:D,A10,Menu!A:A,"GEM") -> 2 | C10: =COUNTIFS(Menu!D:D,A10,Menu!A:A,"NOTABLE") -> 3 | D10: =B10+C10 -> 5
A11: Decisions & Review | B11: =COUNTIFS(Menu!D:D,A11,Menu!A:A,"GEM") -> 1 | C11: =COUNTIFS(Menu!D:D,A11,Menu!A:A,"NOTABLE") -> 3 | D11: =B11+C11 -> 4
A12: Content (Podcast/Video/Music) | B12: =COUNTIFS(Menu!D:D,A12,Menu!A:A,"GEM") -> 2 | C12: =COUNTIFS(Menu!D:D,A12,Menu!A:A,"NOTABLE") -> 2 | D12: =B12+C12 -> 4
A13: Analytics & Growth | B13: =COUNTIFS(Menu!D:D,A13,Menu!A:A,"GEM") -> 2 | C13: =COUNTIFS(Menu!D:D,A13,Menu!A:A,"NOTABLE") -> 0 | D13: =B13+C13 -> 2
... A19: Utilities & Misc | B19: =COUNTIFS(Menu!D:D,A19,Menu!A:A,"GEM") -> 1 | C19: =COUNTIFS(Menu!D:D,A19,Menu!A:A,"NOTABLE") -> 7 | D19: =B19+C19 -> 8
A20: TOTAL | B20: =SUM(B2:B19) -> 39 | C20: =SUM(C2:C19) -> 106 | D20: =SUM(D2:D19) -> 145
